{
 "cells": [
  {
   "cell_type": "markdown",
   "metadata": {},
   "source": [
    "## Excepciones en Python\n",
    "\n",
    "Una excepciÃ³n es el bloque de cÃ³digo que se lanza cuando se produce un error en la ejecuciÃ³n de un programa.\n",
    "\n",
    "De hecho a lo largo del tema ya os habrÃ©is encontrado con excepciones, por ejemplo, cuando intentamos dividir un nÃºmero por cero, o cuando intentamos acceder a un elemento de una lista que no existe.\n",
    "\n",
    "Cuando ejecutamos cÃ³digo que puede fallar (y casi todo el cÃ³digo puede fallar), debemos manerar  de manera adecuada las excepciones que se generan.\n",
    "\n",
    "### Manejo errores\n",
    "\n",
    "Si alguna excepciÃ³n ocurre en algÃºn lugar de nuestro programa y no es capturada en ese punto, va subiendo (burbujeando) por la pila de llamadas hasta que es capturada en algÃºn punto o el programa termina. Si en toda la pia de llamadas no hay ningÃºn manejador de excepciones, el programa termina y se muestra un mensaje de error.\n",
    "\n",
    "En Python, las excepciones se manejan con bloques `try-except`. El bloque `try` contiene el cÃ³digo que puede lanzar una excepciÃ³n. El bloque `except` contiene el cÃ³digo que se ejecuta cuando se lanza una excepciÃ³n.\n",
    "\n",
    "```python\n",
    "try:\n",
    "    return a // b\n",
    "except:\n",
    "    print(\"Error: divisiÃ³n por cero\")\n",
    "```\n",
    "\n",
    "La pila de llamadas o `stack trace` es el listado de llamadas que se han realizado hasta llegar al punto donde se ha producido la excepciÃ³n, dependiendo de lo anidado que estÃ© el cÃ³digo, la pila de llamadas puede ser muy larga.\n",
    "\n",
    "```python\n",
    "def f1(a):\n",
    "    return 12 / a\n",
    "\n",
    "def f2(a):\n",
    "    return f1(a - 2)\n",
    "\n",
    "def f3(a):\n",
    "    return f2(a + 1)\n",
    "\n",
    "print(f3(0))\n",
    "\n",
    "Traceback (most recent call last):\n",
    "  File \"exceptions.py\", line 10, in <module>\n",
    "    print(f3(0))\n",
    "  File \"exceptions.py\", line 7, in f3\n",
    "    return f2(a + 1)\n",
    "  File \"exceptions.py\", line 4, in f2\n",
    "    return f1(a - 2)\n",
    "  File \"exceptions.py\", line 2, in f1\n",
    "    return 12 / a\n",
    "ZeroDivisionError: division by zero\n",
    "```"
   ]
  },
  {
   "cell_type": "markdown",
   "metadata": {},
   "source": [
    "### Especificando expceciones\n",
    "\n",
    "En el siguiente ejemplo mejoraremos el cÃ³digo anterior, capturando distintos tipos de excepciones predefinidas.\n",
    "\n",
    "* `TypeError` se lanza cuando se intenta realizar una operaciÃ³n no permitida con un tipo de dato.\n",
    "* `ZeroDivisionError` se lanza cuando se intenta dividir por cero.\n",
    "* `Exception` para cualquier otro error que se produzca.\n",
    "\n",
    "```python\n",
    "def intdiv(a, b):\n",
    "    try:\n",
    "        result = a // b\n",
    "    except TypeError:\n",
    "        print('Check operands. Some of them seems strange...')\n",
    "    except ZeroDivisionError:\n",
    "        print('Please do not divide by zero...')\n",
    "    except Exception:\n",
    "        print('Ups. Something went wrong...'\n",
    "\n",
    "\n",
    ">>> intdiv(3, 0)\n",
    "Please do not divide by zero...\n",
    ">>> intdiv(3, 'a')\n",
    "Check operands. Some of them seems strange...\n",
    "```\n",
    "\n",
    "### Excepciones predefinidas\n",
    "\n",
    "En Python existen muchas excepciones predefinidas, las mÃ¡s comunes son:\n",
    "\n",
    "* `Exception`: Clase base para todas las excepciones.\n",
    "* `AttributeError`: Se lanza cuando un objeto no tiene un atributo.\n",
    "* `EOFError`: Se lanza cuando se intenta leer mÃ¡s allÃ¡ del final de un fichero.\n",
    "* `IOError`: Se lanza cuando se produce un error de entrada/salida.\n",
    "* `ImportError`: Se lanza cuando falla una importaciÃ³n.\n",
    "* `IndexError`: Se lanza cuando se intenta acceder a un Ã­ndice de una lista fuera de rango.\n",
    "* `KeyError`: Se lanza cuando se intenta acceder a una clave de un diccionario que no existe.\n",
    "* `KeyboardInterrupt`: Se lanza cuando se interrumpe la ejecuciÃ³n del programa (por ejemplo, con Ctrl+C).\n",
    "* `NameError`: Se lanza cuando se intenta acceder a una variable que no existe.\n",
    "* `OSError`: Se lanza cuando se produce un error del sistema operativo.\n",
    "* `SyntaxError`: Se lanza cuando se produce un error de sintaxis.\n",
    "* `TypeError`: Se lanza cuando se intenta realizar una operaciÃ³n no permitida con un tipo de dato.\n",
    "* `ValueError`: Se lanza cuando se intenta realizar una operaciÃ³n no permitida con un valor.\n",
    "* ...\n",
    "\n",
    "#### Agrupando excepciones\n",
    "\n",
    "Si nos interesa tratar diferentes excepciones con el mismo comportamiento, es posible agruparlas en una Ãºnica lÃ­nea.\n",
    "\n",
    "```python\n",
    "def intdiv(a, b):\n",
    "    try:\n",
    "        result = a // b\n",
    "    except (TypeError, ZeroDivisionError):\n",
    "        print('Check operands: Some of them caused errors...')\n",
    "    except Exception:\n",
    "        print('Ups. Something went wrong...')\n",
    "```\n",
    "\n",
    "### Variantes en el tratamiento de excepciones\n",
    "\n",
    "Python proporciona la clÃ¡usula `else` para saber que todo ha ido bien y que no se ha lanzado ninguna excepciÃ³n. Esto es relevante a la hora de manejar los errores.\n",
    "\n",
    "De igual modo, tenemos a nuestra disposiciÃ³n la clÃ¡usula `finally` que se ejecuta siempre, independientemente de si ha habido o no ha habido error.\n",
    "\n",
    "Veamos un ejemplo de ambos:\n",
    "  \n",
    "```python \n",
    "values = [4, 2, 7]\n",
    "\n",
    "try:\n",
    "    r = values[3]\n",
    "except IndexError:\n",
    "    print('Error: Index not in list')\n",
    "else:\n",
    "    print(f'El valor en ese Ã­ndice es: {r}')\n",
    "finally:\n",
    "    print('Have a good day!')\n",
    "\n",
    ">>> Error: Index not in list\n",
    ">>> Have a good day!\n",
    "```\n",
    "\n",
    "### Mostrando errores\n",
    "\n",
    "AdemÃ¡s de capturar las excepciones podemos mostrar sus mensajes de error asociados. Para ello tendremos que hacer uso de la palabra reservada `as` junto a un nombre de variable que contendrÃ¡ el objeto de la excepciÃ³n.\n",
    "\n",
    "Veamos este comportamiento siguiendo con el ejemplo anterior:\n",
    "\n",
    "```python\n",
    "try:\n",
    "    print(values[3])\n",
    "except IndexError as err:\n",
    "    print(err)\n",
    "\n",
    ">>> list index out of range\n",
    "```\t\n",
    "\n",
    "Una vez capturada la excepciÃ³n podemos elaborar un mensaje de error mÃ¡s descriptivo y mostrarlo al usuario.\n",
    "\n",
    "```python\n",
    "try:\n",
    "    print(values[3])\n",
    "except IndexError as err:\n",
    "    print(f'Something went wrong: {err}')\n",
    "\n",
    ">>> Something went wrong: list index out of range\n",
    "```\n",
    "\n",
    "### Elevando excepciones\n",
    "\n",
    "Es habitual que nuestro programa tenga que lanzar (elevar o levantar) una excepciÃ³n (predefinida o propia). Para ello tendremos que hacer uso de la sentencia `raise`.\n",
    "\n",
    "> **Nota**: Elevar es sinÃ³nimo de lanzar o levantar. Es la prÃ¡ctica de crear o relanzar una excepciÃ³n, y que otro cÃ³digo la capture y maneje.\n",
    "\n",
    "Supongamos una funciÃ³n que suma dos valores enteros. En el caso de que alguno de los operandos no sea entero, elevaremos una excepciÃ³n indicando esta circunstancia:\n",
    "\n",
    "```python\n",
    "def sum(a, b):\n",
    "    if not isinstance(a, int) or not isinstance(b, int):\n",
    "        raise TypeError('Both operands must be integers')\n",
    "    return a + b\n",
    "\n",
    ">>> sum(3, 4)\n",
    "7\n",
    "\n",
    ">>> sum(3, 'a')\n",
    "TypeError: Both operands must be integers\n",
    "```\n",
    "\n",
    "### JerarquÃ­a de excepciones\n",
    "\n",
    "Todas las excepciones predefinidas en Python heredan de la clase Exception y de la clase BaseException (mÃ¡s allÃ¡ de heredar, obviamente, de object).\n",
    "\n",
    "> ðŸ’¡ El mÃ©todo `mro()` nos permite ver la jerarquÃ­a de clases de una excepciÃ³n.\n",
    "\n",
    "```python\n",
    "TypeError.mro()\n",
    "[<class 'TypeError'>, <class 'Exception'>, <class 'BaseException'>, <class 'object'>]\n",
    "\n",
    "ZeroDivisionError.mro()\n",
    "[<class 'ZeroDivisionError'>, <class 'ArithmeticError'>, <class 'Exception'>, <class 'BaseException'>, <class 'object'>]\n",
    "\n",
    "IndexError.mro()\n",
    "[<class 'IndexError'>, <class 'LookupError'>, <class 'Exception'>, <class 'BaseException'>, <class 'object'>]\n",
    "\n",
    "FileNotFoundError.mro()\n",
    "[<class 'FileNotFoundError'>, <class 'OSError'>, <class 'Exception'>, <class 'BaseException'>, <class 'object'>]\n",
    "```\n",
    "\n",
    "A continuaciÃ³n se muestra un diagrama con las excepciones mÃ¡s comunes y su jerarquÃ­a:\n",
    "\n",
    "```cmd\t\n",
    "BaseException\n",
    "â”œâ”€â”€ BaseExceptionGroup\n",
    "â”œâ”€â”€ GeneratorExit\n",
    "â”œâ”€â”€ KeyboardInterrupt\n",
    "â”œâ”€â”€ SystemExit\n",
    "â””â”€â”€ Exception\n",
    "    â”œâ”€â”€ ArithmeticError\n",
    "    â”‚    â”œâ”€â”€ FloatingPointError\n",
    "    â”‚    â”œâ”€â”€ OverflowError\n",
    "    â”‚    â””â”€â”€ ZeroDivisionError\n",
    "    â”œâ”€â”€ AssertionError\n",
    "    â”œâ”€â”€ AttributeError\n",
    "    â”œâ”€â”€ BufferError\n",
    "    â”œâ”€â”€ EOFError\n",
    "    â”œâ”€â”€ ExceptionGroup [BaseExceptionGroup]\n",
    "    â”œâ”€â”€ ImportError\n",
    "    â”‚    â””â”€â”€ ModuleNotFoundError\n",
    "    â”œâ”€â”€ LookupError\n",
    "    â”‚    â”œâ”€â”€ IndexError\n",
    "    â”‚    â””â”€â”€ KeyError\n",
    "    â”œâ”€â”€ MemoryError\n",
    "    â”œâ”€â”€ NameError\n",
    "    â”‚    â””â”€â”€ UnboundLocalError\n",
    "    â”œâ”€â”€ OSError\n",
    "    â”‚    â”œâ”€â”€ BlockingIOError\n",
    "    â”‚    â”œâ”€â”€ ChildProcessError\n",
    "    â”‚    â”œâ”€â”€ ConnectionError\n",
    "    â”‚    â”‚    â”œâ”€â”€ BrokenPipeError\n",
    "    â”‚    â”‚    â”œâ”€â”€ ConnectionAbortedError\n",
    "    â”‚    â”‚    â”œâ”€â”€ ConnectionRefusedError\n",
    "    â”‚    â”‚    â””â”€â”€ ConnectionResetError\n",
    "    â”‚    â”œâ”€â”€ FileExistsError\n",
    "    â”‚    â”œâ”€â”€ FileNotFoundError\n",
    "    â”‚    â”œâ”€â”€ InterruptedError\n",
    "    â”‚    â”œâ”€â”€ IsADirectoryError\n",
    "    â”‚    â”œâ”€â”€ NotADirectoryError\n",
    "    â”‚    â”œâ”€â”€ PermissionError\n",
    "    â”‚    â”œâ”€â”€ ProcessLookupError\n",
    "    â”‚    â””â”€â”€ TimeoutError\n",
    "    â”œâ”€â”€ ReferenceError\n",
    "    â”œâ”€â”€ RuntimeError\n",
    "    â”‚    â”œâ”€â”€ NotImplementedError\n",
    "    â”‚    â””â”€â”€ RecursionError\n",
    "    â”œâ”€â”€ StopAsyncIteration\n",
    "    â”œâ”€â”€ StopIteration\n",
    "    â”œâ”€â”€ SyntaxError\n",
    "    â”‚    â””â”€â”€ IndentationError\n",
    "    â”‚         â””â”€â”€ TabError\n",
    "    â”œâ”€â”€ SystemError\n",
    "    â”œâ”€â”€ TypeError\n",
    "    â”œâ”€â”€ ValueError\n",
    "    â”‚    â””â”€â”€ UnicodeError\n",
    "    â”‚         â”œâ”€â”€ UnicodeDecodeError\n",
    "    â”‚         â”œâ”€â”€ UnicodeEncodeError\n",
    "    â”‚         â””â”€â”€ UnicodeTranslateError\n",
    "    â””â”€â”€ Warning\n",
    "        â”œâ”€â”€ BytesWarning\n",
    "        â”œâ”€â”€ DeprecationWarning\n",
    "        â”œâ”€â”€ EncodingWarning\n",
    "        â”œâ”€â”€ FutureWarning\n",
    "        â”œâ”€â”€ ImportWarning\n",
    "        â”œâ”€â”€ PendingDeprecationWarning\n",
    "        â”œâ”€â”€ ResourceWarning\n",
    "        â”œâ”€â”€ RuntimeWarning\n",
    "        â”œâ”€â”€ SyntaxWarning\n",
    "        â”œâ”€â”€ UnicodeWarning\n",
    "        â””â”€â”€ UserWarning\n",
    "```\n"
   ]
  },
  {
   "cell_type": "markdown",
   "metadata": {},
   "source": [
    "### Creando excepciones propias\n",
    "\n",
    "Python ofrece una gran cantidad de excepciones predefinidas. Hasta ahora hemos visto cÃ³mo gestionar y manejar este tipo de excepciones. Pero hay ocasiones en las que nos puede interesar crear nuestras propias excepciones. Para ello simplemente tendremos que crear una clase heredando de Exception, la clase base para todas las excepciones.\n",
    "\n",
    "Veamos un ejemplo en el que creamos una excepciÃ³n propia controlando que el valor sea un nÃºmero entero:\n",
    "\n",
    "```python\n",
    "class NotIntError(Exception):\n",
    "    pass\n",
    "\n",
    "values = (4, 7, 2.11, 9)\n",
    "\n",
    "for value in values:\n",
    "    if not isinstance(value, int):\n",
    "        raise NotIntError(value)\n",
    "\n",
    ">>> NotIntError: 2.11\n",
    "```\n",
    "\n",
    "**Mensaje personalizado**\n",
    "\n",
    "Podemos personalizar la excepciÃ³n propia aÃ±adiendo un mensaje como valor por defecto. Siguiendo el ejemplo anterior, veamos cÃ³mo introducimos esta informaciÃ³n:\n",
    "\n",
    "```python\n",
    "class NotIntError(Exception):\n",
    "    def __init__(self, value):\n",
    "        self.value = value\n",
    "\n",
    "    def __str__(self):\n",
    "        return f'{self.value} is not an integer'\n",
    "\n",
    "\n",
    "values = (4, 7, 2.11, 9)\n",
    "\n",
    "for value in values:\n",
    "    if not isinstance(value, int):\n",
    "        raise NotIntError(value)\n",
    "\n",
    ">>> NotIntError: 2.11 is not an integer\n",
    "```\n",
    "\n",
    "Otra opciÃ³n es pasar el mensaje como parÃ¡metro al crear la excepciÃ³n, este atributo `message` es el que se muestra cuando se lanza la excepciÃ³n, y pertenece a la clase base `Exception`.\n",
    "\n",
    "```python\n",
    "class NotIntError(Exception):\n",
    "    def __init__(self, value, message='This module only works with integers. Sorry!'):\n",
    "      self.value = value\n",
    "      super().__init__(message)\n",
    "\n",
    "\n",
    "\n",
    "values = (4, 7, 2.11, 9)\n",
    "\n",
    "for value in values:\n",
    "    if not isinstance(value, int):\n",
    "        raise NotIntError()\n",
    "\n",
    ">>> NotIntError: This module only works with integers. Sorry!\n",
    "```\n",
    "\n",
    "> **Notas finales**:<br>\n",
    ">Las excepciones son un mecanismo muy potente para controlar los errores que se producen en nuestros programas. Es importante saber manejarlas correctamente para que nuestros programas sean robustos y no se detengan ante el primer error que se produzca.\n",
    ">\n",
    ">Las excepciones tienen un coste computacional, por lo que no es recomendable abusar de ellas. Es mejor prevenir los errores que lanzar excepciones.\n",
    ">\n",
    ">Las excepciones no se deben usar como valor de retorno de una funciÃ³n. Si una funciÃ³n puede devolver un valor o lanzar una excepciÃ³n, es mejor que devuelva el valor o que lance la excepciÃ³n, pero no ambas cosas.\n",
    "\n"
   ]
  }
 ],
 "metadata": {
  "language_info": {
   "name": "python"
  }
 },
 "nbformat": 4,
 "nbformat_minor": 2
}
